[2024-02-12T22:13:27.129+0000] {scheduler_job_runner.py:1586} WARNING - Marking task instance <TaskInstance: ny_taxi-load_to_pg.download_data manual__2024-02-12T22:01:15.737543+00:00 [queued]> stuck in queued as failed. If the task instance has available retries, it will be retried.
[2024-02-12T22:13:27.518+0000] {scheduler_job_runner.py:781} ERROR - Executor reports task instance <TaskInstance: ny_taxi-load_to_pg.download_data manual__2024-02-12T22:01:15.737543+00:00 [queued]> finished (failed) although the task says it's queued. (Info: None) Was the task killed externally?
