[2024-02-12T21:31:23.723+0000] {taskinstance.py:1956} INFO - Dependencies all met for dep_context=non-requeueable deps ti=<TaskInstance: ny_taxi-load_to_pg.download_data manual__2024-02-12T21:31:22.729565+00:00 [queued]>
[2024-02-12T21:31:23.732+0000] {taskinstance.py:1956} INFO - Dependencies all met for dep_context=requeueable deps ti=<TaskInstance: ny_taxi-load_to_pg.download_data manual__2024-02-12T21:31:22.729565+00:00 [queued]>
[2024-02-12T21:31:23.732+0000] {taskinstance.py:2170} INFO - Starting attempt 1 of 1
[2024-02-12T21:31:23.745+0000] {taskinstance.py:2191} INFO - Executing <Task(PythonOperator): download_data> on 2024-02-12 21:31:22.729565+00:00
[2024-02-12T21:31:23.749+0000] {standard_task_runner.py:60} INFO - Started process 517 to run task
[2024-02-12T21:31:23.751+0000] {standard_task_runner.py:87} INFO - Running: ['***', 'tasks', 'run', 'ny_taxi-load_to_pg', 'download_data', 'manual__2024-02-12T21:31:22.729565+00:00', '--job-id', '3', '--raw', '--subdir', 'DAGS_FOLDER/dag_ny_taxi_load_to_pg.py', '--cfg-path', '/tmp/tmpshlrufo5']
[2024-02-12T21:31:23.752+0000] {standard_task_runner.py:88} INFO - Job 3: Subtask download_data
[2024-02-12T21:31:23.792+0000] {task_command.py:423} INFO - Running <TaskInstance: ny_taxi-load_to_pg.download_data manual__2024-02-12T21:31:22.729565+00:00 [running]> on host f0f65c017ce6
[2024-02-12T21:31:23.855+0000] {taskinstance.py:2480} INFO - Exporting env vars: AIRFLOW_CTX_DAG_OWNER='***' AIRFLOW_CTX_DAG_ID='ny_taxi-load_to_pg' AIRFLOW_CTX_TASK_ID='download_data' AIRFLOW_CTX_EXECUTION_DATE='2024-02-12T21:31:22.729565+00:00' AIRFLOW_CTX_TRY_NUMBER='1' AIRFLOW_CTX_DAG_RUN_ID='manual__2024-02-12T21:31:22.729565+00:00'
[2024-02-12T21:31:24.127+0000] {taskinstance.py:2698} ERROR - Task failed with exception
Traceback (most recent call last):
  File "/home/airflow/.local/lib/python3.8/site-packages/airflow/models/taskinstance.py", line 433, in _execute_task
    result = execute_callable(context=context, **execute_callable_kwargs)
  File "/home/airflow/.local/lib/python3.8/site-packages/airflow/operators/python.py", line 199, in execute
    return_value = self.execute_callable()
  File "/home/airflow/.local/lib/python3.8/site-packages/airflow/operators/python.py", line 216, in execute_callable
    return self.python_callable(*self.op_args, **self.op_kwargs)
  File "/opt/airflow/dags/download_data.py", line 18, in download_data
    response.raise_for_status()
  File "/home/airflow/.local/lib/python3.8/site-packages/requests/models.py", line 1021, in raise_for_status
    raise HTTPError(http_error_msg, response=self)
requests.exceptions.HTTPError: 404 Client Error: Not Found for url: https://github.com/DataTalksClub/nyc-tlc-data/releases/download/green/trip%20data/green_tripdata_2019-01.csv
[2024-02-12T21:31:24.138+0000] {taskinstance.py:1138} INFO - Marking task as FAILED. dag_id=ny_taxi-load_to_pg, task_id=download_data, execution_date=20240212T213122, start_date=20240212T213123, end_date=20240212T213124
[2024-02-12T21:31:24.149+0000] {standard_task_runner.py:107} ERROR - Failed to execute job 3 for task download_data (404 Client Error: Not Found for url: https://github.com/DataTalksClub/nyc-tlc-data/releases/download/green/trip%20data/green_tripdata_2019-01.csv; 517)
[2024-02-12T21:31:24.165+0000] {local_task_job_runner.py:234} INFO - Task exited with return code 1
[2024-02-12T21:31:24.188+0000] {taskinstance.py:3280} INFO - 0 downstream tasks scheduled from follow-on schedule check
