[2024-02-12T22:22:59.424+0000] {taskinstance.py:1956} INFO - Dependencies all met for dep_context=non-requeueable deps ti=<TaskInstance: ny_taxi-load_to_pg.download_data manual__2024-02-12T22:22:56.727998+00:00 [queued]>
[2024-02-12T22:22:59.434+0000] {taskinstance.py:1956} INFO - Dependencies all met for dep_context=requeueable deps ti=<TaskInstance: ny_taxi-load_to_pg.download_data manual__2024-02-12T22:22:56.727998+00:00 [queued]>
[2024-02-12T22:22:59.435+0000] {taskinstance.py:2170} INFO - Starting attempt 1 of 1
[2024-02-12T22:22:59.447+0000] {taskinstance.py:2191} INFO - Executing <Task(PythonOperator): download_data> on 2024-02-12 22:22:56.727998+00:00
[2024-02-12T22:22:59.452+0000] {standard_task_runner.py:60} INFO - Started process 93 to run task
[2024-02-12T22:22:59.454+0000] {standard_task_runner.py:87} INFO - Running: ['***', 'tasks', 'run', 'ny_taxi-load_to_pg', 'download_data', 'manual__2024-02-12T22:22:56.727998+00:00', '--job-id', '17', '--raw', '--subdir', 'DAGS_FOLDER/dag_ny_taxi_load_to_pg.py', '--cfg-path', '/tmp/tmp7n2wwfo4']
[2024-02-12T22:22:59.455+0000] {standard_task_runner.py:88} INFO - Job 17: Subtask download_data
[2024-02-12T22:22:59.495+0000] {task_command.py:423} INFO - Running <TaskInstance: ny_taxi-load_to_pg.download_data manual__2024-02-12T22:22:56.727998+00:00 [running]> on host 7b7b8b9b0fa9
[2024-02-12T22:22:59.567+0000] {taskinstance.py:2480} INFO - Exporting env vars: AIRFLOW_CTX_DAG_OWNER='***' AIRFLOW_CTX_DAG_ID='ny_taxi-load_to_pg' AIRFLOW_CTX_TASK_ID='download_data' AIRFLOW_CTX_EXECUTION_DATE='2024-02-12T22:22:56.727998+00:00' AIRFLOW_CTX_TRY_NUMBER='1' AIRFLOW_CTX_DAG_RUN_ID='manual__2024-02-12T22:22:56.727998+00:00'
[2024-02-12T22:23:01.467+0000] {taskinstance.py:2698} ERROR - Task failed with exception
Traceback (most recent call last):
  File "/home/airflow/.local/lib/python3.8/site-packages/airflow/models/taskinstance.py", line 433, in _execute_task
    result = execute_callable(context=context, **execute_callable_kwargs)
  File "/home/airflow/.local/lib/python3.8/site-packages/airflow/operators/python.py", line 199, in execute
    return_value = self.execute_callable()
  File "/home/airflow/.local/lib/python3.8/site-packages/airflow/operators/python.py", line 216, in execute_callable
    return self.python_callable(*self.op_args, **self.op_kwargs)
  File "/opt/airflow/dags/download_data.py", line 25, in download_data
    with open(f"/mnt/ny_taxi/green_tripdata_{year}-{month:02}.csv.gz", "wb") as f:
FileNotFoundError: [Errno 2] No such file or directory: '/mnt/ny_taxi/green_tripdata_2019-01.csv.gz'
[2024-02-12T22:23:01.478+0000] {taskinstance.py:1138} INFO - Marking task as FAILED. dag_id=ny_taxi-load_to_pg, task_id=download_data, execution_date=20240212T222256, start_date=20240212T222259, end_date=20240212T222301
[2024-02-12T22:23:01.496+0000] {standard_task_runner.py:107} ERROR - Failed to execute job 17 for task download_data ([Errno 2] No such file or directory: '/mnt/ny_taxi/green_tripdata_2019-01.csv.gz'; 93)
[2024-02-12T22:23:01.517+0000] {local_task_job_runner.py:234} INFO - Task exited with return code 1
[2024-02-12T22:23:01.541+0000] {taskinstance.py:3280} INFO - 0 downstream tasks scheduled from follow-on schedule check
