[2024-02-12T22:48:58.347+0000] {taskinstance.py:1956} INFO - Dependencies all met for dep_context=non-requeueable deps ti=<TaskInstance: ny_taxi-load_to_pg.upload_to_pg manual__2024-02-12T22:45:05.917083+00:00 [queued]>
[2024-02-12T22:48:58.357+0000] {taskinstance.py:1956} INFO - Dependencies all met for dep_context=requeueable deps ti=<TaskInstance: ny_taxi-load_to_pg.upload_to_pg manual__2024-02-12T22:45:05.917083+00:00 [queued]>
[2024-02-12T22:48:58.358+0000] {taskinstance.py:2170} INFO - Starting attempt 1 of 1
[2024-02-12T22:48:58.372+0000] {taskinstance.py:2191} INFO - Executing <Task(PythonOperator): upload_to_pg> on 2024-02-12 22:45:05.917083+00:00
[2024-02-12T22:48:58.377+0000] {standard_task_runner.py:60} INFO - Started process 485 to run task
[2024-02-12T22:48:58.379+0000] {standard_task_runner.py:87} INFO - Running: ['***', 'tasks', 'run', 'ny_taxi-load_to_pg', 'upload_to_pg', 'manual__2024-02-12T22:45:05.917083+00:00', '--job-id', '20', '--raw', '--subdir', 'DAGS_FOLDER/dag_ny_taxi_load_to_pg.py', '--cfg-path', '/tmp/tmpper28_va']
[2024-02-12T22:48:58.380+0000] {standard_task_runner.py:88} INFO - Job 20: Subtask upload_to_pg
[2024-02-12T22:48:58.422+0000] {task_command.py:423} INFO - Running <TaskInstance: ny_taxi-load_to_pg.upload_to_pg manual__2024-02-12T22:45:05.917083+00:00 [running]> on host 7b7b8b9b0fa9
[2024-02-12T22:48:58.498+0000] {taskinstance.py:2480} INFO - Exporting env vars: AIRFLOW_CTX_DAG_OWNER='***' AIRFLOW_CTX_DAG_ID='ny_taxi-load_to_pg' AIRFLOW_CTX_TASK_ID='upload_to_pg' AIRFLOW_CTX_EXECUTION_DATE='2024-02-12T22:45:05.917083+00:00' AIRFLOW_CTX_TRY_NUMBER='1' AIRFLOW_CTX_DAG_RUN_ID='manual__2024-02-12T22:45:05.917083+00:00'
[2024-02-12T22:48:59.544+0000] {taskinstance.py:2698} ERROR - Task failed with exception
Traceback (most recent call last):
  File "/home/airflow/.local/lib/python3.8/site-packages/airflow/models/taskinstance.py", line 433, in _execute_task
    result = execute_callable(context=context, **execute_callable_kwargs)
  File "/home/airflow/.local/lib/python3.8/site-packages/airflow/operators/python.py", line 199, in execute
    return_value = self.execute_callable()
  File "/home/airflow/.local/lib/python3.8/site-packages/airflow/operators/python.py", line 216, in execute_callable
    return self.python_callable(*self.op_args, **self.op_kwargs)
  File "/opt/airflow/dags/upload_to_pg.py", line 16, in upload_to_pg
    df = pd.read_csv(file)
  File "/home/airflow/.local/lib/python3.8/site-packages/pandas/io/parsers/readers.py", line 912, in read_csv
    return _read(filepath_or_buffer, kwds)
  File "/home/airflow/.local/lib/python3.8/site-packages/pandas/io/parsers/readers.py", line 577, in _read
    parser = TextFileReader(filepath_or_buffer, **kwds)
  File "/home/airflow/.local/lib/python3.8/site-packages/pandas/io/parsers/readers.py", line 1407, in __init__
    self._engine = self._make_engine(f, self.engine)
  File "/home/airflow/.local/lib/python3.8/site-packages/pandas/io/parsers/readers.py", line 1661, in _make_engine
    self.handles = get_handle(
  File "/home/airflow/.local/lib/python3.8/site-packages/pandas/io/common.py", line 753, in get_handle
    handle = gzip.GzipFile(  # type: ignore[assignment]
  File "/usr/local/lib/python3.8/gzip.py", line 173, in __init__
    fileobj = self.myfileobj = builtins.open(filename, mode or 'rb')
FileNotFoundError: [Errno 2] No such file or directory: 'green_tripdata_2019-01.csv.gz'
[2024-02-12T22:48:59.555+0000] {taskinstance.py:1138} INFO - Marking task as FAILED. dag_id=ny_taxi-load_to_pg, task_id=upload_to_pg, execution_date=20240212T224505, start_date=20240212T224858, end_date=20240212T224859
[2024-02-12T22:48:59.567+0000] {standard_task_runner.py:107} ERROR - Failed to execute job 20 for task upload_to_pg ([Errno 2] No such file or directory: 'green_tripdata_2019-01.csv.gz'; 485)
[2024-02-12T22:48:59.597+0000] {local_task_job_runner.py:234} INFO - Task exited with return code 1
[2024-02-12T22:48:59.619+0000] {taskinstance.py:3280} INFO - 0 downstream tasks scheduled from follow-on schedule check
