[2024-02-12T22:51:42.912+0000] {taskinstance.py:1956} INFO - Dependencies all met for dep_context=non-requeueable deps ti=<TaskInstance: ny_taxi-load_to_pg.download_data manual__2024-02-12T22:51:42.071407+00:00 [queued]>
[2024-02-12T22:51:42.923+0000] {taskinstance.py:1956} INFO - Dependencies all met for dep_context=requeueable deps ti=<TaskInstance: ny_taxi-load_to_pg.download_data manual__2024-02-12T22:51:42.071407+00:00 [queued]>
[2024-02-12T22:51:42.923+0000] {taskinstance.py:2170} INFO - Starting attempt 1 of 1
[2024-02-12T22:51:42.936+0000] {taskinstance.py:2191} INFO - Executing <Task(PythonOperator): download_data> on 2024-02-12 22:51:42.071407+00:00
[2024-02-12T22:51:42.941+0000] {standard_task_runner.py:60} INFO - Started process 529 to run task
[2024-02-12T22:51:42.943+0000] {standard_task_runner.py:87} INFO - Running: ['***', 'tasks', 'run', 'ny_taxi-load_to_pg', 'download_data', 'manual__2024-02-12T22:51:42.071407+00:00', '--job-id', '21', '--raw', '--subdir', 'DAGS_FOLDER/dag_ny_taxi_load_to_pg.py', '--cfg-path', '/tmp/tmpciw0hld7']
[2024-02-12T22:51:42.944+0000] {standard_task_runner.py:88} INFO - Job 21: Subtask download_data
[2024-02-12T22:51:42.986+0000] {task_command.py:423} INFO - Running <TaskInstance: ny_taxi-load_to_pg.download_data manual__2024-02-12T22:51:42.071407+00:00 [running]> on host 7b7b8b9b0fa9
[2024-02-12T22:51:43.065+0000] {taskinstance.py:2480} INFO - Exporting env vars: AIRFLOW_CTX_DAG_OWNER='***' AIRFLOW_CTX_DAG_ID='ny_taxi-load_to_pg' AIRFLOW_CTX_TASK_ID='download_data' AIRFLOW_CTX_EXECUTION_DATE='2024-02-12T22:51:42.071407+00:00' AIRFLOW_CTX_TRY_NUMBER='1' AIRFLOW_CTX_DAG_RUN_ID='manual__2024-02-12T22:51:42.071407+00:00'
[2024-02-12T22:52:23.385+0000] {local_task_job_runner.py:302} WARNING - State of this instance has been externally set to failed. Terminating instance.
[2024-02-12T22:52:23.388+0000] {process_utils.py:131} INFO - Sending 15 to group 529. PIDs of all processes in the group: [529]
[2024-02-12T22:52:23.389+0000] {process_utils.py:86} INFO - Sending the signal 15 to group 529
[2024-02-12T22:52:23.391+0000] {taskinstance.py:2450} ERROR - Received SIGTERM. Terminating subprocesses.
[2024-02-12T22:52:23.484+0000] {process_utils.py:79} INFO - Process psutil.Process(pid=529, status='terminated', exitcode=0, started='22:51:42') (529) terminated with exit code 0
